<?xml version="1.0"?>
<robot xmlns:xacro="http://www.ros.org/wiki/xacro" name="robot4_xacro">
<xacro:include filename="$(find erl_ass1_pkg)/urdf/macro_robot4.xacro"/>
<xacro:include filename="$(find erl_ass1_pkg)/urdf/robot4.gazebo"/>
  <!-- _______ROBOT MODEL______-->
  <link name="link_chassis">
    <!-- pose and inertial -->
    <pose>0 0 0.1 0 0 0</pose>
    <xacro:box_inertial mass="5" x="0.5" y="0.3" z="0.07" rpy="0 0 0" xyz="0 0 0.1"/>
    <!-- body -->
    <collision name="collision_chassis">
      <xacro:chassis_geometry />
    </collision>
    <visual>
      <origin rpy="0 0 0" xyz="0 0 0"/>
      <xacro:chassis_geometry />
      <material name="blue"/>
    </visual>
    <!-- caster front -->
    <collision name="caster_front_collision">
      <origin rpy=" 0 0 0" xyz="0.35 0 -0.05"/>
      <xacro:sphere_geometry rad="0.05" />
    </collision>
    <visual name="caster_front_visual">
      <origin rpy=" 0 0 0" xyz="0.2 0 -0.05"/>
      <xacro:sphere_geometry rad="0.05" />
    </visual>
  </link>

  <link name="link_right_wheel">
    <xacro:cyl_inertial mass="0.2" r="0.1" h="0.04" rpy="0 1.5707 1.5707" xyz="0 0 0"/>
    <collision name="link_right_wheel_collision">
      <origin rpy="0 1.5707 1.5707" xyz="0 0 0"/>
      <xacro:wheel_geometry />
    </collision>
    <visual name="link_right_wheel_visual">
      <origin rpy="0 1.5707 1.5707" xyz="0 0 0"/>
      <xacro:wheel_geometry />
      <material name="red"/>
    </visual>
  </link>

  <link name="link_left_wheel">
    <xacro:cyl_inertial mass="0.2" r="0.1" h="0.04" rpy="0 1.5707 1.5707" xyz="0 0 0"/>
    <collision name="link_left_wheel_collision">
      <origin rpy="0 1.5707 1.5707" xyz="0 0 0"/>
      <xacro:wheel_geometry />
    </collision>
    <visual name="link_left_wheel_visual">
      <origin rpy="0 1.5707 1.5707" xyz="0 0 0"/>
      <xacro:wheel_geometry />
      <material name="red"/>
    </visual>
  </link>

  <joint name="joint_right_wheel" type="continuous">
    <origin rpy="0 0 0" xyz="-0.05 0.15 0"/>
    <child link="link_right_wheel"/>
    <parent link="link_chassis"/>
    <axis rpy="0 0 0" xyz="0 1 0"/>
    <xacro:continuous />
  </joint>

  <joint name="joint_left_wheel" type="continuous">
    <origin rpy="0 0 0" xyz="-0.05 -0.15 0"/>
    <child link="link_left_wheel"/>
    <parent link="link_chassis"/>
    <axis rpy="0 0 0" xyz="0 1 0"/>
    <xacro:continuous />
  </joint>

  <link name="fixed_camera_link">
    <xacro:box_inertial mass="1e-5" x="0.1" y="0.1" z="0.25" rpy="0 0 0" xyz="0 0 0"/>
	  <collision>
	    <origin xyz="0 0 0" rpy="0 0 0"/>
	    <geometry>
        <box size="0.1 0.1 0.25"/>
      </geometry>
	  </collision>
	  <visual>
	    <origin xyz="0 0 0" rpy="0 0 0"/>
	    <geometry>
        <box size="0.1 0.1 0.25"/>
      </geometry>
	    <material name="blue"/>
	  </visual>
  </link>

  <joint name="fixed_camera_joint" type="fixed">
    <axis xyz="0 0 1" />
	  <origin xyz="0.1 0 0.0535" rpy="0 0 0"/>
	  <child link="fixed_camera_link"/>
	  <parent link="link_chassis"/>
  </joint>
  
  <link name="camera_link">
    <xacro:box_inertial mass="1e-5" x="0.05" y="0.05" z="0.05" rpy="0 0.174533 0" xyz="0 0 0.025"/>
	  <collision>
	    <origin xyz="0 0 0.025" rpy="0 0.174533 0"/>
	    <xacro:cube_geometry side="0.05" />
	  </collision>
	  <visual>
	    <origin xyz="0 0 0.025" rpy="0 0.174533 0"/>
	    <xacro:cube_geometry side="0.05" />
	    <material name="red"/>
	  </visual>
  </link>
  
  <joint name="continuous_camera_joint" type="continuous">
	    <axis xyz="0 0 1" />
	    <origin xyz="0 0 0.125" rpy="0 0 0"/>
	    <parent link="fixed_camera_link"/>
	    <child link="camera_link"/> 
      <xacro:continuous />
	 </joint>
</robot>
